Workbook

Sheet Budget
B1: Deer Ridge Apartments | C1: (drnd) | E1: Year 1 Budget · Sep-26 – Aug-27
B3: Units: | C3: 163 | D3: Total Income - | E3: =R95 | F3: Total Expense - | G3: =R318 | H3: NOI - | I3: =R319 | J3: Interest - | K3: =R324 | L3: Principal - | M3: =ABS(R388+R389+R390) | N3: Cash Flow - | O3: =I3-K3-M3 | P3: Cash on Cash - | Q3: =IF($C$4>0,O3/$C$4,"")
B4: Capital: | C4: 0
A6: GL Code | B6: GL Name | C6: Notes | D6: Driver | E6: Sep-26 | F6: Oct-26 | G6: Nov-26 | H6: Dec-26 | I6: Jan-27 | J6: Feb-27 | K6: Mar-27 | L6: Apr-27 | M6: May-27 | N6: Jun-27 | O6: Jul-27 | P6: Aug-27 | R6: Total Year 1 Budget | T6: Year 1 UW Budget | U6: Minot Budget at 163 units | X6: Total Per Unit | Y6: Per Unit / Month | Z6: Notes for Budget Upload
A7: 4991 | B7: INCOME
A8: 4992 | B8: RENTAL INCOME
A9: 4993 | B9: NET GROSS POTENTIAL RENT
A10: 4994 | B10: TENANT GROSS POTENTIAL | D10: rent roll GPR | E10: 276505 | F10: 276505 | G10: 276505 | H10: 276505 | I10: 276505 | J10: 276505 | K10: 276505 | L10: 276505 | M10: 276505 | N10: 276505 | O10: 276505 | P10: 276505 | R10: =SUM(E10:P10) | T10: 3219092.9 | U10: 2810093.9 | X10: =R10/$C$3 | Y10: =R10/$C$3/12
A11: 4995 | B11: HAP CONTRACT RENT | R11: =SUM(E11:P11) | X11: =R11/$C$3 | Y11: =R11/$C$3/12
A12: 4996 | B12: HAP VOUCHER RENT | R12: =SUM(E12:P12) | U12: 26592.81 | X12: =R12/$C$3 | Y12: =R12/$C$3/12
A13: 5003 | B13: LOSS/GAIN TO LEASE | D13: LTL burnoff | E13: -24280.78 | F13: -22502.47 | G13: -20724.17 | H13: -18945.87 | I13: -17167.56 | J13: -15389.26 | K13: -13610.95 | L13: -11832.64 | M13: -10054.34 | N13: -8276.03 | O13: -6497.72 | P13: -4719.41 | R13: =SUM(E13:P13) | T13: -80477.323 | U13: -376509.1 | X13: =R13/$C$3 | Y13: =R13/$C$3/12
A14: 5004 | B14: TOTAL NET GROSS POTENTIAL RENT | E14: =SUM(E10:E13) | F14: =SUM(F10:F13) | G14: =SUM(G10:G13) | H14: =SUM(H10:H13) | I14: =SUM(I10:I13) | J14: =SUM(J10:J13) | K14: =SUM(K10:K13) | L14: =SUM(L10:L13) | ... P14: =SUM(P10:P13) | R14: =SUM(E14:P14) | X14: =R14/$C$3 | Y14: =R14/$C$3/12
A15: 5017 | B15: CONCESSIONS
A16: 5018 | B16: BOND CONCESSION | R16: =SUM(E16:P16) | X16: =R16/$C$3 | Y16: =R16/$C$3/12
A17: 5019 | B17: PEP CONCESSION | D17: UW cat 2 share | E17: -752.23 | F17: -752.23 | G17: -752.24 | H17: -752.24 | I17: -752.24 | J17: -752.24 | K17: -752.24 | L17: -752.24 | M17: -752.24 | N17: -752.24 | O17: -752.24 | P17: -752.24 | R17: =SUM(E17:P17) | U17: -5284.68 | X17: =R17/$C$3 | Y17: =R17/$C$3/12
A18: 5020 | B18: RENT CONCESSION - RECURRING | D18: UW cat 2 share | E18: -192.41 | F18: -192.41 | G18: -192.41 | H18: -192.41 | I18: -192.42 | J18: -192.42 | K18: -192.42 | L18: -192.42 | M18: -192.42 | N18: -192.42 | O18: -192.42 | P18: -192.42 | R18: =SUM(E18:P18) | U18: -1351.78 | X18: =R18/$C$3 | Y18: =R18/$C$3/12
A19: 5021 | B19: RENT CONCESSION - ONE-TIME | D19: UW cat 2 share | E19: -59.86 | F19: -59.86 | G19: -59.86 | H19: -59.86 | I19: -59.86 | J19: -59.86 | K19: -59.86 | L19: -59.86 | M19: -59.86 | N19: -59.86 | O19: -59.86 | P19: -59.87 | R19: =SUM(E19:P19) | U19: -420.54 | X19: =R19/$C$3 | Y19: =R19/$C$3/12
A20: 5022 | B20: CONCESSION RECAPTURE | R20: =SUM(E20:P20) | X20: =R20/$C$3 | Y20: =R20/$C$3/12
A21: 5023 | B21: RENEWAL CONCESSION | R21: =SUM(E21:P21) | X21: =R21/$C$3 | Y21: =R21/$C$3/12
A22: 5024 | B22: MOVE-IN CONCESSION | D22: UW cat 2 share | E22: -182.48 | F22: -182.48 | G22: -182.48 | H22: -182.49 | I22: -182.49 | J22: -182.49 | K22: -182.49 | L22: -182.49 | M22: -182.49 | N22: -182.49 | O22: -182.49 | P22: -182.49 | R22: =SUM(E22:P22) | U22: -1282.02 | X22: =R22/$C$3 | Y22: =R22/$C$3/12
A23: 5025 | B23: REFERRAL CONCESSION | D23: UW cat 2 share | E23: -195.52 | F23: -195.52 | G23: -195.52 | H23: -195.52 | I23: -195.52 | J23: -195.52 | K23: -195.52 | L23: -195.52 | M23: -195.52 | N23: -195.52 | O23: -195.53 | P23: -195.53 | R23: =SUM(E23:P23) | U23: -1373.6 | X23: =R23/$C$3 | Y23: =R23/$C$3/12
A24: 5027 | B24: SUMMER STORAGE CONCESSION | R24: =SUM(E24:P24) | X24: =R24/$C$3 | Y24: =R24/$C$3/12
A25: 5028 | B25: FIRE CONCESSION | R25: =SUM(E25:P25) | X25: =R25/$C$3 | Y25: =R25/$C$3/12
A26: 5029 | B26: TOTAL CONCESSIONS | E26: =SUM(E16:E25) | F26: =SUM(F16:F25) | G26: =SUM(G16:G25) | H26: =SUM(H16:H25) | I26: =SUM(I16:I25) | J26: =SUM(J16:J25) | K26: =SUM(K16:K25) | L26: =SUM(L16:L25) | ... P26: =SUM(P16:P25) | R26: =SUM(E26:P26) | T26: -16095.465 | X26: =R26/$C$3 | Y26: =R26/$C$3/12
A27: 5030 | B27: RENTAL LOSS
A28: 5031 | B28: Less: VACANCY | D28: vacancy % of GPR | E28: -13825.25 | F28: -13825.25 | G28: -13825.25 | H28: -13825.25 | I28: -13825.25 | J28: -13825.25 | K28: -13825.25 | L28: -13825.25 | M28: -13825.25 | N28: -13825.25 | O28: -13825.25 | P28: -13825.25 | R28: =SUM(E28:P28) | U28: -78107.05 | X28: =R28/$C$3 | Y28: =R28/$C$3/12
A29: 5032 | B29: Less: MODELS | R29: =SUM(E29:P29) | X29: =R29/$C$3 | Y29: =R29/$C$3/12
A30: 5033 | B30: Less: ADMIN | R30: =SUM(E30:P30) | U30: -3021.91 | X30: =R30/$C$3 | Y30: =R30/$C$3/12
A31: 5034 | B31: Less: DOWN | R31: =SUM(E31:P31) | X31: =R31/$C$3 | Y31: =R31/$C$3/12
A32: 5035 | B32: Less: CURRENT DELINQUENCY | R32: =SUM(E32:P32) | U32: -6294.37 | X32: =R32/$C$3 | Y32: =R32/$C$3/12
A33: 5036 | B33: PRIOR PERIOD COLLECTIONS | R33: =SUM(E33:P33) | U33: 4586.33 | X33: =R33/$C$3 | Y33: =R33/$C$3/12
A34: 5040 | B34: WRITE-OFFS | R34: =SUM(E34:P34) | X34: =R34/$C$3 | Y34: =R34/$C$3/12
A35: 5049 | B35: TOTAL RENTAL LOSS | E35: =SUM(E28:E34) | F35: =SUM(F28:F34) | G35: =SUM(G28:G34) | H35: =SUM(H28:H34) | I35: =SUM(I28:I34) | J35: =SUM(J28:J34) | K35: =SUM(K28:K34) | L35: =SUM(L28:L34) | ... P35: =SUM(P28:P34) | R35: =SUM(E35:P35) | T35: -160954.65 | X35: =R35/$C$3 | Y35: =R35/$C$3/12
A36: 5070 | B36: TOTAL RENTAL INCOME | E36: =E14+E26+E35 | F36: =F14+F26+F35 | G36: =G14+G26+G35 | H36: =H14+H26+H35 | I36: =I14+I26+I35 | J36: =J14+J26+J35 | K36: =K14+K26+K35 | L36: =L14+L26+L35 | ... P36: =P14+P26+P35 | R36: =SUM(E36:P36) | X36: =R36/$C$3 | Y36: =R36/$C$3/12
A37: 5100 | B37: OTHER INCOME
A38: 5103 | B38: ALARM FEE | R38: =SUM(E38:P38) | X38: =R38/$C$3 | Y38: =R38/$C$3/12
A39: 5104 | B39: AMENITY MEMBERSHIP | R39: =SUM(E39:P39) | X39: =R39/$C$3 | Y39: =R39/$C$3/12
A40: 5105 | B40: APPLICATION FEES | D40: UW cat 5 share | E40: 277.81 | F40: 185.2 | G40: 155.96 | H40: 139.39 | I40: 185.2 | J40: 185.2 | K40: 321.67 | L40: 394.77 | M40: 385.03 | N40: 350.91 | O40: 341.16 | P40: 350.91 | R40: =SUM(E40:P40) | U40: 7687.56 | X40: =R40/$C$3 | Y40: =R40/$C$3/12
A41: 5110 | B41: BAD DEBT RECOVERY | D41: UW cat 5 share | E41: 174.48 | F41: 174.48 | G41: 174.48 | H41: 174.48 | I41: 203.73 | J41: 203.72 | K41: 252.46 | L41: 164.73 | M41: 164.73 | N41: 159.86 | O41: 159.86 | P41: 159.86 | R41: =SUM(E41:P41) | U41: 5089.17 | X41: =R41/$C$3 | Y41: =R41/$C$3/12
A42: 5112 | B42: CELL TOWER RENT | R42: =SUM(E42:P42) | X42: =R42/$C$3 | Y42: =R42/$C$3/12
...

Sheet Summary
B1: Deer Ridge Apartments Year 1 Budget Analysis (Sep-26 – Aug-27)
G2: Unit Count | H2: 163
B4: Account Summary | D4: Year 1 UW Budget | E4: Year 1 Budget | F4: Δ vs UW | G4: Per Unit | H4: Per Unit / Month
A5: 5070 | B5: TOTAL RENTAL INCOME | D5: 2961565.5 | E5: =Budget!R36 | F5: =E5-D5 | G5: =E5/$H$2 | H5: =E5/$H$2/12
A6: 5190 | B6: NET OTHER INCOME | D6: 354851.53 | E6: =Budget!R94 | F6: =E6-D6 | G6: =E6/$H$2 | H6: =E6/$H$2/12
A7: 5500 | B7: TOTAL INCOME | D7: 3316417 | E7: =Budget!R95 | F7: =E7-D7 | G7: =E7/$H$2 | H7: =E7/$H$2/12
A8: 6170 | B8: TOTAL FIXED ADMINISTRATIVE | D8: 56633.7 | E8: =Budget!R111 | F8: =E8-D8 | G8: =E8/$H$2 | H8: =E8/$H$2/12
A9: 6370 | B9: TOTAL ADMINISTRATIVE | D9: 4491.3 | E9: =Budget!R155 | F9: =E9-D9 | G9: =E9/$H$2 | H9: =E9/$H$2/12
A10: 6399 | B10: TOTAL CORPORATE EVENTS | D10: 0 | E10: =Budget!R165 | F10: =E10-D10 | G10: =E10/$H$2 | H10: =E10/$H$2/12
A11: 6470 | B11: TOTAL PAYROLL | D11: 321925 | E11: =Budget!R185 | F11: =E11-D11 | G11: =E11/$H$2 | H11: =E11/$H$2/12
A12: 6570 | B12: TOTAL MARKETING | D12: 26895 | E12: =Budget!R206 | F12: =E12-D12 | G12: =E12/$H$2 | H12: =E12/$H$2/12
A13: 6670 | B13: TOTAL UTILITIES | D13: 188508.56 | E13: =Budget!R231 | F13: =E13-D13 | G13: =E13/$H$2 | H13: =E13/$H$2/12
A14: 6770 | B14: TOTAL IN-HOUSE MAINT | D14: 36713.51 | E14: =Budget!R255 | F14: =E14-D14 | G14: =E14/$H$2 | H14: =E14/$H$2/12
A15: 6870 | B15: TOTAL EXTERIOR/CAM | D15: 4627.82 | E15: =Budget!R270 | F15: =E15-D15 | G15: =E15/$H$2 | H15: =E15/$H$2/12
A16: 6970 | B16: TOTAL CONTRACT SERVICES | D16: 137958.68 | E16: =Budget!R297 | F16: =E16-D16 | G16: =E16/$H$2 | H16: =E16/$H$2/12
A17: 7070 | B17: TOTAL REHAB/REPLACEMENT | D17: 57050 | E17: =Budget!R315 | F17: =E17-D17 | G17: =E17/$H$2 | H17: =E17/$H$2/12
A18: 7099 | B18: TOTAL OPERATING EXPENSES | D18: 1298476.1 | E18: =Budget!R317 | F18: =E18-D18 | G18: =E18/$H$2 | H18: =E18/$H$2/12
A19: 7280 | B19: NET OPERATING INCOME | D19: 2017941 | E19: =Budget!R319 | F19: =E19-D19 | G19: =E19/$H$2 | H19: =E19/$H$2/12
B21: Interest Expense | E21: =Budget!R324
B22: Principal | E22: =ABS(Budget!R388+Budget!R389+Budget!R390)
B23: Special Projects | E23: =Budget!R376
B24: Cash Flow (NOI − debt service) | E24: =E19-E21-E22
B26: Capital Contributions | D26: 0
B27: Cash on Cash Return | E27: =IF(D26>0,E24/D26,"")

Sheet Raw Data
A1: Generated inputs (budgets.inputs)
A2: key | B2: value
A3: gpr.growthPct | B3: 0, 0, 0, 0, 0, 0, 0, 0, 0, 0, 0, 0
A4: gpr.baseMonthly | B4: 276505
A5: ltl.targetPct | B5: 0.025
A6: ltl.rampMonths | B6: 12
A7: ltl.startMonthly | B7: -26474
A8: loan | B8: 0
A9: rate | B9: 0.06
A10: year | B10: 2026
A11: units | B11: 163
A12: uwAbs.4 | B12: 140056.67
A13: uwAbs.5 | B13: 214794.86
A14: uwAbs.6 | B14: 46455
A15: uwAbs.8 | B15: 317725
... A21: uwAbs.14 | B21: 57050
A22: tieNoi | B22: TRUE
A23: capital | B23: 0
A24: mgmtPct | B24: 0.03
A25: tieIncome | B25: TRUE
A26: startMonth | B26: 9
A27: vacancyPct | B27: 0.05, 0.05, 0.05, 0.05, 0.05, 0.05, 0.05, 0.05, 0.05, 0.05, 0.05, 0.05
A28: concessionPct | B28: 0.005
A29: rentalLossPct | B29: 0.05
A31: UW Year-1 by category (tie-out targets)
A32: pcode | B32: label | C32: UW Y1
A33: 1 | B33: Gross Potential Rent | C33: 3219092.9
A34: loss | B34: Loss to Lease | C34: -80477.323
A35: 2 | B35: Concessions | C35: -16095.465
A36: 3 | B36: Rental Loss (Vacancy etc.) | C36: -160954.65
A37: 4 | B37: Utility Income | C37: 140056.67
A38: 5 | B38: Other Income | C38: 214794.86
A39: 6 | B39: Insurance | C39: 46455
A40: 7 | B40: Management Fee | C40: 99492.511
A41: 8 | B41: RE & PP Taxes | C41: 317725
A42: 9 | B42: Admin & Accounting | C42: 61125
A43: 10 | B43: Payroll & Benefits | C43: 321925
A44: 11 | B44: Marketing | C44: 26895
... A47: 14 | B47: Rehab / Reserves | C47: 57050
B48: EGI | C48: 3316417
...
